Defaulting to user installation because normal site-packages is not writeable
ERROR: Invalid requirement: '# Core dependencies for the Discord bot and async operations': Expected package name at the start of dependency specifier
    # Core dependencies for the Discord bot and async operations
    ^
Defaulting to user installation because normal site-packages is not writeable
ERROR: Invalid requirement: 'discord.py==2.3.2  # Discord API wrapper for bot functionality (discord, discord.app_commands)': Expected end or semicolon (after version specifier)
    discord.py==2.3.2  # Discord API wrapper for bot functionality (discord, discord.app_commands)
              ~~~~~~~~~^
Defaulting to user installation because normal site-packages is not writeable
ERROR: Invalid requirement: 'aiohttp==3.9.5     # Asynchronous HTTP client/server for API calls and web server (aiohttp)': Expected end or semicolon (after version specifier)
    aiohttp==3.9.5     # Asynchronous HTTP client/server for API calls and web server (aiohttp)
           ~~~~~~~~~~~~^
Hint: It looks like a path. File 'aiohttp==3.9.5     # Asynchronous HTTP client/server for API calls and web server (aiohttp)' does not exist.
Defaulting to user installation because normal site-packages is not writeable
ERROR: Invalid requirement: 'aiomysql==0.2.0    # Asynchronous MySQL client for database operations (aiomysql)': Expected end or semicolon (after version specifier)
    aiomysql==0.2.0    # Asynchronous MySQL client for database operations (aiomysql)
            ~~~~~~~~~~~^
Defaulting to user installation because normal site-packages is not writeable
ERROR: Invalid requirement: 'redis==5.0.4       # Async Redis client (redis.asyncio)': Expected end or semicolon (after version specifier)
    redis==5.0.4       # Async Redis client (redis.asyncio)
         ~~~~~~~~~~~~~~^
Defaulting to user installation because normal site-packages is not writeable
ERROR: Invalid requirement: 'cryptography==42.0.5  # Fernet encryption and password hashing (cryptography.fernet, cryptography.hazmat.primitives)': Expected end or semicolon (after version specifier)
    cryptography==42.0.5  # Fernet encryption and password hashing (cryptography.fernet, cryptography.hazmat.primitives)
                ~~~~~~~~~~^
Defaulting to user installation because normal site-packages is not writeable
ERROR: Invalid requirement: 'aiohttp-session==2.12.0  # Session management for aiohttp web server (aiohttp_session)': Expected end or semicolon (after version specifier)
    aiohttp-session==2.12.0  # Session management for aiohttp web server (aiohttp_session)
                   ~~~~~~~~~~^
Defaulting to user installation because normal site-packages is not writeable
Requirement already satisfied: jinja2==3.1.2 in ./.local/lib/python3.12/site-packages (3.1.2)
Requirement already satisfied: MarkupSafe>=2.0 in ./.local/lib/python3.12/site-packages (from jinja2==3.1.2) (3.0.2)
Defaulting to user installation because normal site-packages is not writeable
ERROR: Invalid requirement: 'python-dotenv==1.0.1  # Load environment variables from .env (dotenv.load_dotenv)': Expected end or semicolon (after version specifier)
    python-dotenv==1.0.1  # Load environment variables from .env (dotenv.load_dotenv)
                 ~~~~~~~~~^
Defaulting to user installation because normal site-packages is not writeable
ERROR: Invalid requirement: 'Pillow==10.3.0     # Image manipulation for user images (PIL.Image)': Expected end or semicolon (after version specifier)
    Pillow==10.3.0     # Image manipulation for user images (PIL.Image)
          ~~~~~~~~~~~~~^
Defaulting to user installation because normal site-packages is not writeable
ERROR: Invalid requirement: 'PyTZ==2024.1       # Timezone handling (pytz)': Expected end or semicolon (after version specifier)
    PyTZ==2024.1       # Timezone handling (pytz)
        ~~~~~~~~~~~~~~~^
Defaulting to user installation because normal site-packages is not writeable
ERROR: Invalid requirement: 'typing_extensions==4.11.0  # Enhanced typing support (typing.Optional/Dict/List/Any)': Expected end or semicolon (after version specifier)
    typing_extensions==4.11.0  # Enhanced typing support (typing.Optional/Dict/List/Any)
                     ~~~~~~~~~~^
Hint: It looks like a path. File 'typing_extensions==4.11.0  # Enhanced typing support (typing.Optional/Dict/List/Any)' does not exist.
Defaulting to user installation because normal site-packages is not writeable
ERROR: Invalid requirement: 'jsonpickle==3.0.4  # JSON serialization/deserialization (json, enhanced functionality)': Expected end or semicolon (after version specifier)
    jsonpickle==3.0.4  # JSON serialization/deserialization (json, enhanced functionality)
              ~~~~~~~~~^
Hint: It looks like a path. File 'jsonpickle==3.0.4  # JSON serialization/deserialization (json, enhanced functionality)' does not exist.
Defaulting to user installation because normal site-packages is not writeable
ERROR: Invalid requirement: 'regex==2024.5.15   # Advanced regular expression support (re enhancement)': Expected end or semicolon (after version specifier)
    regex==2024.5.15   # Advanced regular expression support (re enhancement)
         ~~~~~~~~~~~~~~^
Defaulting to user installation because normal site-packages is not writeable
ERROR: Invalid requirement: 'pandas==2.2.2      # Data manipulation for CSV files (e.g., get_team_logo_url_from_csv)': Expected end or semicolon (after version specifier)
    pandas==2.2.2      # Data manipulation for CSV files (e.g., get_team_logo_url_from_csv)
          ~~~~~~~~~~~~~^
Defaulting to user installation because normal site-packages is not writeable
Requirement already satisfied: apscheduler==3.10.4 in ./.local/lib/python3.12/site-packages (3.10.4)
Requirement already satisfied: six>=1.4.0 in ./.local/lib/python3.12/site-packages (from apscheduler==3.10.4) (1.17.0)
Requirement already satisfied: pytz in ./.local/lib/python3.12/site-packages (from apscheduler==3.10.4) (2024.1)
Requirement already satisfied: tzlocal!=3.*,>=2.0 in ./.local/lib/python3.12/site-packages (from apscheduler==3.10.4) (5.3.1)
Calculated LOGO_DIR does not exist or is not a directory: /home/container/static/logos
Calculated LOGO_DIR does not exist or is not a directory: /home/container/static/logos
Calculated LOGO_DIR does not exist or is not a directory: /home/container/static/logos
Calculated LOGO_DIR does not exist or is not a directory: /home/container/static/logos
/home/container/.local/lib/python3.12/site-packages/aiomysql/cursors.py:239: Warning: Table 'bets' already exists
  await self._query(query)
/home/container/.local/lib/python3.12/site-packages/aiomysql/cursors.py:239: Warning: Table 'league_teams_logos' already exists
  await self._query(query)
/home/container/.local/lib/python3.12/site-packages/aiomysql/cursors.py:239: Warning: Table 'cappers' already exists
  await self._query(query)
/home/container/.local/lib/python3.12/site-packages/aiomysql/cursors.py:239: Warning: Table 'server_settings' already exists
  await self._query(query)
/home/container/.local/lib/python3.12/site-packages/aiomysql/cursors.py:239: Warning: Table 'subscribers' already exists
  await self._query(query)
/home/container/.local/lib/python3.12/site-packages/aiomysql/cursors.py:239: Warning: Table 'subscriptions' already exists
  await self._query(query)
/home/container/.local/lib/python3.12/site-packages/aiomysql/cursors.py:239: Warning: Table 'unit_records' already exists
  await self._query(query)
/home/container/.local/lib/python3.12/site-packages/aiomysql/cursors.py:239: Warning: Table 'users' already exists
  await self._query(query)
/home/container/.local/lib/python3.12/site-packages/aiomysql/cursors.py:239: Warning: Table 'user_images' already exists
  await self._query(query)
/home/container/.local/lib/python3.12/site-packages/aiomysql/cursors.py:239: Warning: Table 'voice_bet_updates' already exists
  await self._query(query)
Database query fetch_one failed: SELECT id, units, total FROM unit_records WHERE bet_serial = %s AND guild_id = %s AND user_id = %s LIMIT 1... | Params: (202504131546699, 1328126227013439601, 821794684497690695) | Error: (1054, "Unknown column 'id' in 'field list'")
Traceback (most recent call last):
  File "/home/container/bot/data/db_manager.py", line 300, in fetch_one
    await cur.execute(query, params)
  File "/home/container/.local/lib/python3.12/site-packages/aiomysql/cursors.py", line 239, in execute
    await self._query(query)
  File "/home/container/.local/lib/python3.12/site-packages/aiomysql/cursors.py", line 457, in _query
    await conn.query(q)
  File "/home/container/.local/lib/python3.12/site-packages/aiomysql/connection.py", line 469, in query
    await self._read_query_result(unbuffered=unbuffered)
  File "/home/container/.local/lib/python3.12/site-packages/aiomysql/connection.py", line 683, in _read_query_result
    await result.read()
  File "/home/container/.local/lib/python3.12/site-packages/aiomysql/connection.py", line 1164, in read
    first_packet = await self.connection._read_packet()
                   ^^^^^^^^^^^^^^^^^^^^^^^^^^^^^^^^^^^^
  File "/home/container/.local/lib/python3.12/site-packages/aiomysql/connection.py", line 652, in _read_packet
    packet.raise_for_error()
  File "/home/container/.local/lib/python3.12/site-packages/pymysql/protocol.py", line 219, in raise_for_error
    err.raise_mysql_exception(self._data)
  File "/home/container/.local/lib/python3.12/site-packages/pymysql/err.py", line 150, in raise_mysql_exception
    raise errorclass(errno, errval)
pymysql.err.OperationalError: (1054, "Unknown column 'id' in 'field list'")
DatabaseQueryError: Query fetch_one failed: (1054, "Unknown column 'id' in 'field list'") | Query: SELECT id, units, total FROM unit_records WHERE bet_serial = %s AND guild_id = %s AND user_id = %s LIMIT 1
Error checking/correcting unit_record for resolved bet 202504131546699: Query fetch_one failed: (1054, "Unknown column 'id' in 'field list'") | Query: SELECT id, units, total FROM unit_records WHERE bet_serial = %s AND guild_id = %s AND user_id = %s LIMIT 1
Traceback (most recent call last):
  File "/home/container/bot/data/db_manager.py", line 300, in fetch_one
    await cur.execute(query, params)
  File "/home/container/.local/lib/python3.12/site-packages/aiomysql/cursors.py", line 239, in execute
    await self._query(query)
  File "/home/container/.local/lib/python3.12/site-packages/aiomysql/cursors.py", line 457, in _query
    await conn.query(q)
  File "/home/container/.local/lib/python3.12/site-packages/aiomysql/connection.py", line 469, in query
    await self._read_query_result(unbuffered=unbuffered)
  File "/home/container/.local/lib/python3.12/site-packages/aiomysql/connection.py", line 683, in _read_query_result
    await result.read()
  File "/home/container/.local/lib/python3.12/site-packages/aiomysql/connection.py", line 1164, in read
    first_packet = await self.connection._read_packet()
                   ^^^^^^^^^^^^^^^^^^^^^^^^^^^^^^^^^^^^
  File "/home/container/.local/lib/python3.12/site-packages/aiomysql/connection.py", line 652, in _read_packet
    packet.raise_for_error()
  File "/home/container/.local/lib/python3.12/site-packages/pymysql/protocol.py", line 219, in raise_for_error
    err.raise_mysql_exception(self._data)
  File "/home/container/.local/lib/python3.12/site-packages/pymysql/err.py", line 150, in raise_mysql_exception
    raise errorclass(errno, errval)
pymysql.err.OperationalError: (1054, "Unknown column 'id' in 'field list'")

During handling of the above exception, another exception occurred:

Traceback (most recent call last):
  File "/home/container/bot/tasks/startup_checks.py", line 172, in _check_recent_created_resolved_unit_records
    unit_record = await bot.db_manager.fetch_one(unit_query, (bet_serial, guild_id, user_id))
                  ^^^^^^^^^^^^^^^^^^^^^^^^^^^^^^^^^^^^^^^^^^^^^^^^^^^^^^^^^^^^^^^^^^^^^^^^^^^
  File "/home/container/bot/data/db_manager.py", line 306, in fetch_one
    raise DatabaseQueryError(message=f"Query fetch_one failed: {e}", query=query, original_exception=e)
bot.utils.errors.DatabaseQueryError: Query fetch_one failed: (1054, "Unknown column 'id' in 'field list'") | Query: SELECT id, units, total FROM unit_records WHERE bet_serial = %s AND guild_id = %s AND user_id = %s LIMIT 1
Database query fetch_one failed: SELECT id, units, total FROM unit_records WHERE bet_serial = %s AND guild_id = %s AND user_id = %s LIMIT 1... | Params: (202504132211888, 1328126227013439601, 821794684497690695) | Error: (1054, "Unknown column 'id' in 'field list'")
Traceback (most recent call last):
  File "/home/container/bot/data/db_manager.py", line 300, in fetch_one
    await cur.execute(query, params)
  File "/home/container/.local/lib/python3.12/site-packages/aiomysql/cursors.py", line 239, in execute
    await self._query(query)
  File "/home/container/.local/lib/python3.12/site-packages/aiomysql/cursors.py", line 457, in _query
    await conn.query(q)
  File "/home/container/.local/lib/python3.12/site-packages/aiomysql/connection.py", line 469, in query
    await self._read_query_result(unbuffered=unbuffered)
  File "/home/container/.local/lib/python3.12/site-packages/aiomysql/connection.py", line 683, in _read_query_result
    await result.read()
  File "/home/container/.local/lib/python3.12/site-packages/aiomysql/connection.py", line 1164, in read
    first_packet = await self.connection._read_packet()
                   ^^^^^^^^^^^^^^^^^^^^^^^^^^^^^^^^^^^^
  File "/home/container/.local/lib/python3.12/site-packages/aiomysql/connection.py", line 652, in _read_packet
    packet.raise_for_error()
  File "/home/container/.local/lib/python3.12/site-packages/pymysql/protocol.py", line 219, in raise_for_error
    err.raise_mysql_exception(self._data)
  File "/home/container/.local/lib/python3.12/site-packages/pymysql/err.py", line 150, in raise_mysql_exception
    raise errorclass(errno, errval)
pymysql.err.OperationalError: (1054, "Unknown column 'id' in 'field list'")
DatabaseQueryError: Query fetch_one failed: (1054, "Unknown column 'id' in 'field list'") | Query: SELECT id, units, total FROM unit_records WHERE bet_serial = %s AND guild_id = %s AND user_id = %s LIMIT 1
Error checking/correcting unit_record for resolved bet 202504132211888: Query fetch_one failed: (1054, "Unknown column 'id' in 'field list'") | Query: SELECT id, units, total FROM unit_records WHERE bet_serial = %s AND guild_id = %s AND user_id = %s LIMIT 1
Traceback (most recent call last):
  File "/home/container/bot/data/db_manager.py", line 300, in fetch_one
    await cur.execute(query, params)
  File "/home/container/.local/lib/python3.12/site-packages/aiomysql/cursors.py", line 239, in execute
    await self._query(query)
  File "/home/container/.local/lib/python3.12/site-packages/aiomysql/cursors.py", line 457, in _query
    await conn.query(q)
  File "/home/container/.local/lib/python3.12/site-packages/aiomysql/connection.py", line 469, in query
    await self._read_query_result(unbuffered=unbuffered)
  File "/home/container/.local/lib/python3.12/site-packages/aiomysql/connection.py", line 683, in _read_query_result
    await result.read()
  File "/home/container/.local/lib/python3.12/site-packages/aiomysql/connection.py", line 1164, in read
    first_packet = await self.connection._read_packet()
                   ^^^^^^^^^^^^^^^^^^^^^^^^^^^^^^^^^^^^
  File "/home/container/.local/lib/python3.12/site-packages/aiomysql/connection.py", line 652, in _read_packet
    packet.raise_for_error()
  File "/home/container/.local/lib/python3.12/site-packages/pymysql/protocol.py", line 219, in raise_for_error
    err.raise_mysql_exception(self._data)
  File "/home/container/.local/lib/python3.12/site-packages/pymysql/err.py", line 150, in raise_mysql_exception
    raise errorclass(errno, errval)
pymysql.err.OperationalError: (1054, "Unknown column 'id' in 'field list'")

During handling of the above exception, another exception occurred:

Traceback (most recent call last):
  File "/home/container/bot/tasks/startup_checks.py", line 172, in _check_recent_created_resolved_unit_records
    unit_record = await bot.db_manager.fetch_one(unit_query, (bet_serial, guild_id, user_id))
                  ^^^^^^^^^^^^^^^^^^^^^^^^^^^^^^^^^^^^^^^^^^^^^^^^^^^^^^^^^^^^^^^^^^^^^^^^^^^
  File "/home/container/bot/data/db_manager.py", line 306, in fetch_one
    raise DatabaseQueryError(message=f"Query fetch_one failed: {e}", query=query, original_exception=e)
bot.utils.errors.DatabaseQueryError: Query fetch_one failed: (1054, "Unknown column 'id' in 'field list'") | Query: SELECT id, units, total FROM unit_records WHERE bet_serial = %s AND guild_id = %s AND user_id = %s LIMIT 1
Unexpected error loading command load_logos: setup() missing 1 required positional argument: 'guilds'
Traceback (most recent call last):
  File "/home/container/bot/core.py", line 187, in load_commands
    module.setup(self.command_tree) # Modified to pass self.command_tree
    ^^^^^^^^^^^^^^^^^^^^^^^^^^^^^^^
TypeError: setup() missing 1 required positional argument: 'guilds'
Database pool closed or not initialized. Attempting to reconnect.
/home/container/.local/lib/python3.12/site-packages/aiomysql/cursors.py:239: Warning: Table 'bets' already exists
  await self._query(query)
/home/container/.local/lib/python3.12/site-packages/aiomysql/cursors.py:239: Warning: Table 'league_teams_logos' already exists
  await self._query(query)
/home/container/.local/lib/python3.12/site-packages/aiomysql/cursors.py:239: Warning: Table 'cappers' already exists
  await self._query(query)
/home/container/.local/lib/python3.12/site-packages/aiomysql/cursors.py:239: Warning: Table 'server_settings' already exists
  await self._query(query)
/home/container/.local/lib/python3.12/site-packages/aiomysql/cursors.py:239: Warning: Table 'subscribers' already exists
  await self._query(query)
/home/container/.local/lib/python3.12/site-packages/aiomysql/cursors.py:239: Warning: Table 'subscriptions' already exists
  await self._query(query)
/home/container/.local/lib/python3.12/site-packages/aiomysql/cursors.py:239: Warning: Table 'unit_records' already exists
  await self._query(query)
/home/container/.local/lib/python3.12/site-packages/aiomysql/cursors.py:239: Warning: Table 'users' already exists
  await self._query(query)
/home/container/.local/lib/python3.12/site-packages/aiomysql/cursors.py:239: Warning: Table 'user_images' already exists
  await self._query(query)
/home/container/.local/lib/python3.12/site-packages/aiomysql/cursors.py:239: Warning: Table 'voice_bet_updates' already exists
  await self._query(query)
Error handling request
Traceback (most recent call last):
  File "/home/container/.local/lib/python3.12/site-packages/aiohttp/web_protocol.py", line 350, in data_received
    messages, upgraded, tail = self._request_parser.feed_data(data)
                               ^^^^^^^^^^^^^^^^^^^^^^^^^^^^^^^^^^^^
  File "aiohttp/_http_parser.pyx", line 557, in aiohttp._http_parser.HttpParser.feed_data
aiohttp.http_exceptions.BadStatusLine: 400, message:
  Invalid method encountered:

    b'\x14'
      ^
Error handling request
Traceback (most recent call last):
  File "/home/container/.local/lib/python3.12/site-packages/aiohttp/web_protocol.py", line 350, in data_received
    messages, upgraded, tail = self._request_parser.feed_data(data)
                               ^^^^^^^^^^^^^^^^^^^^^^^^^^^^^^^^^^^^
  File "aiohttp/_http_parser.pyx", line 557, in aiohttp._http_parser.HttpParser.feed_data
aiohttp.http_exceptions.BadStatusLine: 400, message:
  Invalid method encountered:

    b'\x14'
      ^
